Workbook

Sheet Setup
A1: Project 1: Large-Scale Evaluation of Modern Search and Sorting Algorithms
A3: Item | B3: Details
A4: Hardware | B4: Intel Core i7-12800H (6 performance + 8 efficiency cores, 20 threads)
A5: Operating system | B5: Windows
A6: Compiler | B6: g++ (MSYS2), flags: -O2 -std=c++17 (OpenMP bonus adds -fopenmp)
A7: Language | B7: C++
A8: Sizes | B8: n = 1,000,000 and n = 100,000,000 integers
A9: Random | B9: n numbers from 0 to n-1, mt19937 seed 42
A10: Nearly sorted | B10: Random numbers sorted, then 1% of positions swapped at random
A11: Reverse sorted | B11: Random numbers sorted largest to smallest
A12: Duplicates | B12: n numbers from 0 to 999 (only 1,000 different values)
A13: Data storage | B13: All data generated in memory (no files); every algorithm sorts a copy of the same array
A14: Sorting time | B14: Average of 5 runs (1M) or 3 runs (100M), wall-clock time with std::chrono
... A20: Skipped run | B20: QuickSort (Lomuto) on 100M duplicates: O(n^2) on many equal values, would take hours

Sheet Sorting Data
A1: Sorting results (program output)
A3: Algorithm | B3: Type | C3: Dataset | D3: n | E3: Time (ms) | F3: Comparisons | G3: Max depth | H3: Extra (MB)
A4: AlphaDev sort | B4: Modern | C4: Random | D4: 1000000 | E4: 73.94 | F4: 22174921 | G4: 13 | H4: 0
A5: PDQSort | B5: Modern | C5: Random | D5: 1000000 | E5: 72.12 | F5: 22900121 | G5: 22 | H5: 0
A6: TwinArray Sort | B6: Modern | C6: Random | D6: 1000000 | E6: 16.34 | F6: 2000000 | G6: 0 | H6: 7.63
A7: Merge sort | B7: Classic | C7: Random | D7: 1000000 | E7: 96.32 | F7: 18674876 | G7: 20 | H7: 3.81
A8: Heap sort | B8: Classic | C8: Random | D8: 1000000 | E8: 118.77 | F8: 36793933 | G8: 0 | H8: 0
A9: QuickSort | B9: Classic | C9: Random | D9: 1000000 | E9: 66.72 | F9: 24880331 | G9: 51 | H9: 0
A10: AlphaDev sort | B10: Modern | C10: Nearly sorted | D10: 1000000 | E10: 17.37 | F10: 19612073 | G10: 17 | H10: 0
A11: PDQSort | B11: Modern | C11: Nearly sorted | D11: 1000000 | E11: 10.9 | F11: 16242358 | G11: 16 | H11: 0
A12: TwinArray Sort | B12: Modern | C12: Nearly sorted | D12: 1000000 | E12: 10.17 | F12: 2000000 | G12: 0 | H12: 7.63
A13: Merge sort | B13: Classic | C13: Nearly sorted | D13: 1000000 | E13: 25.05 | F13: 16437374 | G13: 20 | H13: 3.81
A14: Heap sort | B14: Classic | C14: Nearly sorted | D14: 1000000 | E14: 64.52 | F14: 37704186 | G14: 0 | H14: 0
A15: QuickSort | B15: Classic | C15: Nearly sorted | D15: 1000000 | E15: 25.65 | F15: 25593387 | G15: 83 | H15: 0
... A50: Heap sort | B50: Classic | C50: Duplicates | D50: 100000000 | E50: 17157.19 | F50: 5009558141 | G50: 0 | H50: 0
A51: QuickSort | B51: Classic | C51: Duplicates | D51: 100000000 | E51: skipped | I51: O(n^2) on duplicates, would take hours

Sheet Sorting Summary
A1: Sorting summary (all values are formulas reading 'Sorting Data')
A3: Time (ms), n = 1,000,000
A5: Algorithm | B5: Random | C5: Nearly sorted | D5: Reverse sorted | E5: Duplicates
A6: AlphaDev sort | B6: =IF(COUNTIFS('Sorting Data'!$A$4:$A$51,$A6,'Sorting Data'!$C$4:$C$51,B$5,'Sorting Data'!$D$4:$D$51,1000000,'Sorting Data'!$E$4:$E$51,"skipped")>0,"skipped",SUMIFS('Sorting Data'!$E$4:$E$51,'Sorting Data'!$A$4:$A$51,$A6,'Sorting Data'!$C$4:$C$51,B$5,'Sorting Data'!$D$4:$D$51,1000000)) -> 73.94 | C6: =IF(COUNTIFS('Sorting Data'!$A$4:$A$51,$A6,'Sorting Data'!$C$4:$C$51,C$5,'Sorting Data'!$D$4:$D$51,1000000,'Sorting Data'!$E$4:$E$51,"skipped")>0,"skipped",SUMIFS('Sorting Data'!$E$4:$E$51,'Sorting Data'!$A$4:$A$51,$A6,'Sorting Data'!$C$4:$C$51,C$5,'Sorting Data'!$D$4:$D$51,1000000)) -> 17.37 | D6: =IF(COUNTIFS('Sorting Data'!$A$4:$A$51,$A6,'Sorting Data'!$C$4:$C$51,D$5,'Sorting Data'!$D$4:$D$51,1000000,'Sorting Data'!$E$4:$E$51,"skipped")>0,"skipped",SUMIFS('Sorting Data'!$E$4:$E$51,'Sorting Data'!$A$4:$A$51,$A6,'Sorting Data'!$C$4:$C$51,D$5,'Sorting Data'!$D$4:$D$51,1000000)) -> 14.35 | E6: =IF(COUNTIFS('Sorting Data'!$A$4:$A$51,$A6,'Sorting Data'!$C$4:$C$51,E$5,'Sorting Data'!$D$4:$D$51,1000000,'Sorting Data'!$E$4:$E$51,"skipped")>0,"skipped",SUMIFS('Sorting Data'!$E$4:$E$51,'Sorting Data'!$A$4:$A$51,$A6,'Sorting Data'!$C$4:$C$51,E$5,'Sorting Data'!$D$4:$D$51,1000000)) -> 46.64
A7: PDQSort | B7: =IF(COUNTIFS('Sorting Data'!$A$4:$A$51,$A7,'Sorting Data'!$C$4:$C$51,B$5,'Sorting Data'!$D$4:$D$51,1000000,'Sorting Data'!$E$4:$E$51,"skipped")>0,"skipped",SUMIFS('Sorting Data'!$E$4:$E$51,'Sorting Data'!$A$4:$A$51,$A7,'Sorting Data'!$C$4:$C$51,B$5,'Sorting Data'!$D$4:$D$51,1000000)) -> 72.12 | C7: =IF(COUNTIFS('Sorting Data'!$A$4:$A$51,$A7,'Sorting Data'!$C$4:$C$51,C$5,'Sorting Data'!$D$4:$D$51,1000000,'Sorting Data'!$E$4:$E$51,"skipped")>0,"skipped",SUMIFS('Sorting Data'!$E$4:$E$51,'Sorting Data'!$A$4:$A$51,$A7,'Sorting Data'!$C$4:$C$51,C$5,'Sorting Data'!$D$4:$D$51,1000000)) -> 10.9 | D7: =IF(COUNTIFS('Sorting Data'!$A$4:$A$51,$A7,'Sorting Data'!$C$4:$C$51,D$5,'Sorting Data'!$D$4:$D$51,1000000,'Sorting Data'!$E$4:$E$51,"skipped")>0,"skipped",SUMIFS('Sorting Data'!$E$4:$E$51,'Sorting Data'!$A$4:$A$51,$A7,'Sorting Data'!$C$4:$C$51,D$5,'Sorting Data'!$D$4:$D$51,1000000)) -> 2.11 | E7: =IF(COUNTIFS('Sorting Data'!$A$4:$A$51,$A7,'Sorting Data'!$C$4:$C$51,E$5,'Sorting Data'!$D$4:$D$51,1000000,'Sorting Data'!$E$4:$E$51,"skipped")>0,"skipped",SUMIFS('Sorting Data'!$E$4:$E$51,'Sorting Data'!$A$4:$A$51,$A7,'Sorting Data'!$C$4:$C$51,E$5,'Sorting Data'!$D$4:$D$51,1000000)) -> 38.37
A8: TwinArray Sort | B8: =IF(COUNTIFS('Sorting Data'!$A$4:$A$51,$A8,'Sorting Data'!$C$4:$C$51,B$5,'Sorting Data'!$D$4:$D$51,1000000,'Sorting Data'!$E$4:$E$51,"skipped")>0,"skipped",SUMIFS('Sorting Data'!$E$4:$E$51,'Sorting Data'!$A$4:$A$51,$A8,'Sorting Data'!$C$4:$C$51,B$5,'Sorting Data'!$D$4:$D$51,1000000)) -> 16.34 | C8: =IF(COUNTIFS('Sorting Data'!$A$4:$A$51,$A8,'Sorting Data'!$C$4:$C$51,C$5,'Sorting Data'!$D$4:$D$51,1000000,'Sorting Data'!$E$4:$E$51,"skipped")>0,"skipped",SUMIFS('Sorting Data'!$E$4:$E$51,'Sorting Data'!$A$4:$A$51,$A8,'Sorting Data'!$C$4:$C$51,C$5,'Sorting Data'!$D$4:$D$51,1000000)) -> 10.17 | D8: =IF(COUNTIFS('Sorting Data'!$A$4:$A$51,$A8,'Sorting Data'!$C$4:$C$51,D$5,'Sorting Data'!$D$4:$D$51,1000000,'Sorting Data'!$E$4:$E$51,"skipped")>0,"skipped",SUMIFS('Sorting Data'!$E$4:$E$51,'Sorting Data'!$A$4:$A$51,$A8,'Sorting Data'!$C$4:$C$51,D$5,'Sorting Data'!$D$4:$D$51,1000000)) -> 9.85 | E8: =IF(COUNTIFS('Sorting Data'!$A$4:$A$51,$A8,'Sorting Data'!$C$4:$C$51,E$5,'Sorting Data'!$D$4:$D$51,1000000,'Sorting Data'!$E$4:$E$51,"skipped")>0,"skipped",SUMIFS('Sorting Data'!$E$4:$E$51,'Sorting Data'!$A$4:$A$51,$A8,'Sorting Data'!$C$4:$C$51,E$5,'Sorting Data'!$D$4:$D$51,1000000)) -> 2.21
A9: Merge sort | B9: =IF(COUNTIFS('Sorting Data'!$A$4:$A$51,$A9,'Sorting Data'!$C$4:$C$51,B$5,'Sorting Data'!$D$4:$D$51,1000000,'Sorting Data'!$E$4:$E$51,"skipped")>0,"skipped",SUMIFS('Sorting Data'!$E$4:$E$51,'Sorting Data'!$A$4:$A$51,$A9,'Sorting Data'!$C$4:$C$51,B$5,'Sorting Data'!$D$4:$D$51,1000000)) -> 96.32 | C9: =IF(COUNTIFS('Sorting Data'!$A$4:$A$51,$A9,'Sorting Data'!$C$4:$C$51,C$5,'Sorting Data'!$D$4:$D$51,1000000,'Sorting Data'!$E$4:$E$51,"skipped")>0,"skipped",SUMIFS('Sorting Data'!$E$4:$E$51,'Sorting Data'!$A$4:$A$51,$A9,'Sorting Data'!$C$4:$C$51,C$5,'Sorting Data'!$D$4:$D$51,1000000)) -> 25.05 | D9: =IF(COUNTIFS('Sorting Data'!$A$4:$A$51,$A9,'Sorting Data'!$C$4:$C$51,D$5,'Sorting Data'!$D$4:$D$51,1000000,'Sorting Data'!$E$4:$E$51,"skipped")>0,"skipped",SUMIFS('Sorting Data'!$E$4:$E$51,'Sorting Data'!$A$4:$A$51,$A9,'Sorting Data'!$C$4:$C$51,D$5,'Sorting Data'!$D$4:$D$51,1000000)) -> 25.94 | E9: =IF(COUNTIFS('Sorting Data'!$A$4:$A$51,$A9,'Sorting Data'!$C$4:$C$51,E$5,'Sorting Data'!$D$4:$D$51,1000000,'Sorting Data'!$E$4:$E$51,"skipped")>0,"skipped",SUMIFS('Sorting Data'!$E$4:$E$51,'Sorting Data'!$A$4:$A$51,$A9,'Sorting Data'!$C$4:$C$51,E$5,'Sorting Data'!$D$4:$D$51,1000000)) -> 71.76
A10: Heap sort | B10: =IF(COUNTIFS('Sorting Data'!$A$4:$A$51,$A10,'Sorting Data'!$C$4:$C$51,B$5,'Sorting Data'!$D$4:$D$51,1000000,'Sorting Data'!$E$4:$E$51,"skipped")>0,"skipped",SUMIFS('Sorting Data'!$E$4:$E$51,'Sorting Data'!$A$4:$A$51,$A10,'Sorting Data'!$C$4:$C$51,B$5,'Sorting Data'!$D$4:$D$51,1000000)) -> 118.77 | C10: =IF(COUNTIFS('Sorting Data'!$A$4:$A$51,$A10,'Sorting Data'!$C$4:$C$51,C$5,'Sorting Data'!$D$4:$D$51,1000000,'Sorting Data'!$E$4:$E$51,"skipped")>0,"skipped",SUMIFS('Sorting Data'!$E$4:$E$51,'Sorting Data'!$A$4:$A$51,$A10,'Sorting Data'!$C$4:$C$51,C$5,'Sorting Data'!$D$4:$D$51,1000000)) -> 64.52 | D10: =IF(COUNTIFS('Sorting Data'!$A$4:$A$51,$A10,'Sorting Data'!$C$4:$C$51,D$5,'Sorting Data'!$D$4:$D$51,1000000,'Sorting Data'!$E$4:$E$51,"skipped")>0,"skipped",SUMIFS('Sorting Data'!$E$4:$E$51,'Sorting Data'!$A$4:$A$51,$A10,'Sorting Data'!$C$4:$C$51,D$5,'Sorting Data'!$D$4:$D$51,1000000)) -> 57.93 | E10: =IF(COUNTIFS('Sorting Data'!$A$4:$A$51,$A10,'Sorting Data'!$C$4:$C$51,E$5,'Sorting Data'!$D$4:$D$51,1000000,'Sorting Data'!$E$4:$E$51,"skipped")>0,"skipped",SUMIFS('Sorting Data'!$E$4:$E$51,'Sorting Data'!$A$4:$A$51,$A10,'Sorting Data'!$C$4:$C$51,E$5,'Sorting Data'!$D$4:$D$51,1000000)) -> 94.54
A11: QuickSort | B11: =IF(COUNTIFS('Sorting Data'!$A$4:$A$51,$A11,'Sorting Data'!$C$4:$C$51,B$5,'Sorting Data'!$D$4:$D$51,1000000,'Sorting Data'!$E$4:$E$51,"skipped")>0,"skipped",SUMIFS('Sorting Data'!$E$4:$E$51,'Sorting Data'!$A$4:$A$51,$A11,'Sorting Data'!$C$4:$C$51,B$5,'Sorting Data'!$D$4:$D$51,1000000)) -> 66.72 | C11: =IF(COUNTIFS('Sorting Data'!$A$4:$A$51,$A11,'Sorting Data'!$C$4:$C$51,C$5,'Sorting Data'!$D$4:$D$51,1000000,'Sorting Data'!$E$4:$E$51,"skipped")>0,"skipped",SUMIFS('Sorting Data'!$E$4:$E$51,'Sorting Data'!$A$4:$A$51,$A11,'Sorting Data'!$C$4:$C$51,C$5,'Sorting Data'!$D$4:$D$51,1000000)) -> 25.65 | D11: =IF(COUNTIFS('Sorting Data'!$A$4:$A$51,$A11,'Sorting Data'!$C$4:$C$51,D$5,'Sorting Data'!$D$4:$D$51,1000000,'Sorting Data'!$E$4:$E$51,"skipped")>0,"skipped",SUMIFS('Sorting Data'!$E$4:$E$51,'Sorting Data'!$A$4:$A$51,$A11,'Sorting Data'!$C$4:$C$51,D$5,'Sorting Data'!$D$4:$D$51,1000000)) -> 20.68 | E11: =IF(COUNTIFS('Sorting Data'!$A$4:$A$51,$A11,'Sorting Data'!$C$4:$C$51,E$5,'Sorting Data'!$D$4:$D$51,1000000,'Sorting Data'!$E$4:$E$51,"skipped")>0,"skipped",SUMIFS('Sorting Data'!$E$4:$E$51,'Sorting Data'!$A$4:$A$51,$A11,'Sorting Data'!$C$4:$C$51,E$5,'Sorting Data'!$D$4:$D$51,1000000)) -> 246.44
A13: Time (ms), n = 100,000,000
A15: Algorithm | B15: Random | C15: Nearly sorted | D15: Reverse sorted | E15: Duplicates
A16: AlphaDev sort | B16: =IF(COUNTIFS('Sorting Data'!$A$4:$A$51,$A16,'Sorting Data'!$C$4:$C$51,B$15,'Sorting Data'!$D$4:$D$51,100000000,'Sorting Data'!$E$4:$E$51,"skipped")>0,"skipped",SUMIFS('Sorting Data'!$E$4:$E$51,'Sorting Data'!$A$4:$A$51,$A16,'Sorting Data'!$C$4:$C$51,B$15,'Sorting Data'!$D$4:$D$51,100000000)) -> 9853.18 | C16: =IF(COUNTIFS('Sorting Data'!$A$4:$A$51,$A16,'Sorting Data'!$C$4:$C$51,C$15,'Sorting Data'!$D$4:$D$51,100000000,'Sorting Data'!$E$4:$E$51,"skipped")>0,"skipped",SUMIFS('Sorting Data'!$E$4:$E$51,'Sorting Data'!$A$4:$A$51,$A16,'Sorting Data'!$C$4:$C$51,C$15,'Sorting Data'!$D$4:$D$51,100000000)) -> 2034.64 | D16: =IF(COUNTIFS('Sorting Data'!$A$4:$A$51,$A16,'Sorting Data'!$C$4:$C$51,D$15,'Sorting Data'!$D$4:$D$51,100000000,'Sorting Data'!$E$4:$E$51,"skipped")>0,"skipped",SUMIFS('Sorting Data'!$E$4:$E$51,'Sorting Data'!$A$4:$A$51,$A16,'Sorting Data'!$C$4:$C$51,D$15,'Sorting Data'!$D$4:$D$51,100000000)) -> 1690.93 | E16: =IF(COUNTIFS('Sorting Data'!$A$4:$A$51,$A16,'Sorting Data'!$C$4:$C$51,E$15,'Sorting Data'!$D$4:$D$51,100000000,'Sorting Data'!$E$4:$E$51,"skipped")>0,"skipped",SUMIFS('Sorting Data'!$E$4:$E$51,'Sorting Data'!$A$4:$A$51,$A16,'Sorting Data'!$C$4:$C$51,E$15,'Sorting Data'!$D$4:$D$51,100000000)) -> 4924.99
A17: PDQSort | B17: =IF(COUNTIFS('Sorting Data'!$A$4:$A$51,$A17,'Sorting Data'!$C$4:$C$51,B$15,'Sorting Data'!$D$4:$D$51,100000000,'Sorting Data'!$E$4:$E$51,"skipped")>0,"skipped",SUMIFS('Sorting Data'!$E$4:$E$51,'Sorting Data'!$A$4:$A$51,$A17,'Sorting Data'!$C$4:$C$51,B$15,'Sorting Data'!$D$4:$D$51,100000000)) -> 10157.52 | C17: =IF(COUNTIFS('Sorting Data'!$A$4:$A$51,$A17,'Sorting Data'!$C$4:$C$51,C$15,'Sorting Data'!$D$4:$D$51,100000000,'Sorting Data'!$E$4:$E$51,"skipped")>0,"skipped",SUMIFS('Sorting Data'!$E$4:$E$51,'Sorting Data'!$A$4:$A$51,$A17,'Sorting Data'!$C$4:$C$51,C$15,'Sorting Data'!$D$4:$D$51,100000000)) -> 1474.29 | D17: =IF(COUNTIFS('Sorting Data'!$A$4:$A$51,$A17,'Sorting Data'!$C$4:$C$51,D$15,'Sorting Data'!$D$4:$D$51,100000000,'Sorting Data'!$E$4:$E$51,"skipped")>0,"skipped",SUMIFS('Sorting Data'!$E$4:$E$51,'Sorting Data'!$A$4:$A$51,$A17,'Sorting Data'!$C$4:$C$51,D$15,'Sorting Data'!$D$4:$D$51,100000000)) -> 189.51 | E17: =IF(COUNTIFS('Sorting Data'!$A$4:$A$51,$A17,'Sorting Data'!$C$4:$C$51,E$15,'Sorting Data'!$D$4:$D$51,100000000,'Sorting Data'!$E$4:$E$51,"skipped")>0,"skipped",SUMIFS('Sorting Data'!$E$4:$E$51,'Sorting Data'!$A$4:$A$51,$A17,'Sorting Data'!$C$4:$C$51,E$15,'Sorting Data'!$D$4:$D$51,100000000)) -> 3828.35
A18: TwinArray Sort | B18: =IF(COUNTIFS('Sorting Data'!$A$4:$A$51,$A18,'Sorting Data'!$C$4:$C$51,B$15,'Sorting Data'!$D$4:$D$51,100000000,'Sorting Data'!$E$4:$E$51,"skipped")>0,"skipped",SUMIFS('Sorting Data'!$E$4:$E$51,'Sorting Data'!$A$4:$A$51,$A18,'Sorting Data'!$C$4:$C$51,B$15,'Sorting Data'!$D$4:$D$51,100000000)) -> 4055.94 | C18: =IF(COUNTIFS('Sorting Data'!$A$4:$A$51,$A18,'Sorting Data'!$C$4:$C$51,C$15,'Sorting Data'!$D$4:$D$51,100000000,'Sorting Data'!$E$4:$E$51,"skipped")>0,"skipped",SUMIFS('Sorting Data'!$E$4:$E$51,'Sorting Data'!$A$4:$A$51,$A18,'Sorting Data'!$C$4:$C$51,C$15,'Sorting Data'!$D$4:$D$51,100000000)) -> 1076.45 | D18: =IF(COUNTIFS('Sorting Data'!$A$4:$A$51,$A18,'Sorting Data'!$C$4:$C$51,D$15,'Sorting Data'!$D$4:$D$51,100000000,'Sorting Data'!$E$4:$E$51,"skipped")>0,"skipped",SUMIFS('Sorting Data'!$E$4:$E$51,'Sorting Data'!$A$4:$A$51,$A18,'Sorting Data'!$C$4:$C$51,D$15,'Sorting Data'!$D$4:$D$51,100000000)) -> 887.99 | E18: =IF(COUNTIFS('Sorting Data'!$A$4:$A$51,$A18,'Sorting Data'!$C$4:$C$51,E$15,'Sorting Data'!$D$4:$D$51,100000000,'Sorting Data'!$E$4:$E$51,"skipped")>0,"skipped",SUMIFS('Sorting Data'!$E$4:$E$51,'Sorting Data'!$A$4:$A$51,$A18,'Sorting Data'!$C$4:$C$51,E$15,'Sorting Data'!$D$4:$D$51,100000000)) -> 144.43
A19: Merge sort | B19: =IF(COUNTIFS('Sorting Data'!$A$4:$A$51,$A19,'Sorting Data'!$C$4:$C$51,B$15,'Sorting Data'!$D$4:$D$51,100000000,'Sorting Data'!$E$4:$E$51,"skipped")>0,"skipped",SUMIFS('Sorting Data'!$E$4:$E$51,'Sorting Data'!$A$4:$A$51,$A19,'Sorting Data'!$C$4:$C$51,B$15,'Sorting Data'!$D$4:$D$51,100000000)) -> 12654.04 | C19: =IF(COUNTIFS('Sorting Data'!$A$4:$A$51,$A19,'Sorting Data'!$C$4:$C$51,C$15,'Sorting Data'!$D$4:$D$51,100000000,'Sorting Data'!$E$4:$E$51,"skipped")>0,"skipped",SUMIFS('Sorting Data'!$E$4:$E$51,'Sorting Data'!$A$4:$A$51,$A19,'Sorting Data'!$C$4:$C$51,C$15,'Sorting Data'!$D$4:$D$51,100000000)) -> 3262.32 | D19: =IF(COUNTIFS('Sorting Data'!$A$4:$A$51,$A19,'Sorting Data'!$C$4:$C$51,D$15,'Sorting Data'!$D$4:$D$51,100000000,'Sorting Data'!$E$4:$E$51,"skipped")>0,"skipped",SUMIFS('Sorting Data'!$E$4:$E$51,'Sorting Data'!$A$4:$A$51,$A19,'Sorting Data'!$C$4:$C$51,D$15,'Sorting Data'!$D$4:$D$51,100000000)) -> 3188.43 | E19: =IF(COUNTIFS('Sorting Data'!$A$4:$A$51,$A19,'Sorting Data'!$C$4:$C$51,E$15,'Sorting Data'!$D$4:$D$51,100000000,'Sorting Data'!$E$4:$E$51,"skipped")>0,"skipped",SUMIFS('Sorting Data'!$E$4:$E$51,'Sorting Data'!$A$4:$A$51,$A19,'Sorting Data'!$C$4:$C$51,E$15,'Sorting Data'!$D$4:$D$51,100000000)) -> 7797.43
A20: Heap sort | B20: =IF(COUNTIFS('Sorting Data'!$A$4:$A$51,$A20,'Sorting Data'!$C$4:$C$51,B$15,'Sorting Data'!$D$4:$D$51,100000000,'Sorting Data'!$E$4:$E$51,"skipped")>0,"skipped",SUMIFS('Sorting Data'!$E$4:$E$51,'Sorting Data'!$A$4:$A$51,$A20,'Sorting Data'!$C$4:$C$51,B$15,'Sorting Data'!$D$4:$D$51,100000000)) -> 28907.63 | C20: =IF(COUNTIFS('Sorting Data'!$A$4:$A$51,$A20,'Sorting Data'!$C$4:$C$51,C$15,'Sorting Data'!$D$4:$D$51,100000000,'Sorting Data'!$E$4:$E$51,"skipped")>0,"skipped",SUMIFS('Sorting Data'!$E$4:$E$51,'Sorting Data'!$A$4:$A$51,$A20,'Sorting Data'!$C$4:$C$51,C$15,'Sorting Data'!$D$4:$D$51,100000000)) -> 7402.48 | D20: =IF(COUNTIFS('Sorting Data'!$A$4:$A$51,$A20,'Sorting Data'!$C$4:$C$51,D$15,'Sorting Data'!$D$4:$D$51,100000000,'Sorting Data'!$E$4:$E$51,"skipped")>0,"skipped",SUMIFS('Sorting Data'!$E$4:$E$51,'Sorting Data'!$A$4:$A$51,$A20,'Sorting Data'!$C$4:$C$51,D$15,'Sorting Data'!$D$4:$D$51,100000000)) -> 6842.22 | E20: =IF(COUNTIFS('Sorting Data'!$A$4:$A$51,$A20,'Sorting Data'!$C$4:$C$51,E$15,'Sorting Data'!$D$4:$D$51,100000000,'Sorting Data'!$E$4:$E$51,"skipped")>0,"skipped",SUMIFS('Sorting Data'!$E$4:$E$51,'Sorting Data'!$A$4:$A$51,$A20,'Sorting Data'!$C$4:$C$51,E$15,'Sorting Data'!$D$4:$D$51,100000000)) -> 17157.19
A21: QuickSort | B21: =IF(COUNTIFS('Sorting Data'!$A$4:$A$51,$A21,'Sorting Data'!$C$4:$C$51,B$15,'Sorting Data'!$D$4:$D$51,100000000,'Sorting Data'!$E$4:$E$51,"skipped")>0,"skipped",SUMIFS('Sorting Data'!$E$4:$E$51,'Sorting Data'!$A$4:$A$51,$A21,'Sorting Data'!$C$4:$C$51,B$15,'Sorting Data'!$D$4:$D$51,100000000)) -> 8698.53 | C21: =IF(COUNTIFS('Sorting Data'!$A$4:$A$51,$A21,'Sorting Data'!$C$4:$C$51,C$15,'Sorting Data'!$D$4:$D$51,100000000,'Sorting Data'!$E$4:$E$51,"skipped")>0,"skipped",SUMIFS('Sorting Data'!$E$4:$E$51,'Sorting Data'!$A$4:$A$51,$A21,'Sorting Data'!$C$4:$C$51,C$15,'Sorting Data'!$D$4:$D$51,100000000)) -> 3492.91 | D21: =IF(COUNTIFS('Sorting Data'!$A$4:$A$51,$A21,'Sorting Data'!$C$4:$C$51,D$15,'Sorting Data'!$D$4:$D$51,100000000,'Sorting Data'!$E$4:$E$51,"skipped")>0,"skipped",SUMIFS('Sorting Data'!$E$4:$E$51,'Sorting Data'!$A$4:$A$51,$A21,'Sorting Data'!$C$4:$C$51,D$15,'Sorting Data'!$D$4:$D$51,100000000)) -> 2425.27 | E21: =IF(COUNTIFS('Sorting Data'!$A$4:$A$51,$A21,'Sorting Data'!$C$4:$C$51,E$15,'Sorting Data'!$D$4:$D$51,100000000,'Sorting Data'!$E$4:$E$51,"skipped")>0,"skipped",SUMIFS('Sorting Data'!$E$4:$E$51,'Sorting Data'!$A$4:$A$51,$A21,'Sorting Data'!$C$4:$C$51,E$15,'Sorting Data'!$D$4:$D$51,100000000)) -> skipped
A23: Comparisons, n = 1,000,000
A25: Algorithm | B25: Random | C25: Nearly sorted | D25: Reverse sorted | E25: Duplicates
A26: AlphaDev sort | B26: =IF(COUNTIFS('Sorting Data'!$A$4:$A$51,$A26,'Sorting Data'!$C$4:$C$51,B$25,'Sorting Data'!$D$4:$D$51,1000000,'Sorting Data'!$E$4:$E$51,"skipped")>0,"skipped",SUMIFS('Sorting Data'!$F$4:$F$51,'Sorting Data'!$A$4:$A$51,$A26,'Sorting Data'!$C$4:$C$51,B$25,'Sorting Data'!$D$4:$D$51,1000000)) -> 22174921 | C26: =IF(COUNTIFS('Sorting Data'!$A$4:$A$51,$A26,'Sorting Data'!$C$4:$C$51,C$25,'Sorting Data'!$D$4:$D$51,1000000,'Sorting Data'!$E$4:$E$51,"skipped")>0,"skipped",SUMIFS('Sorting Data'!$F$4:$F$51,'Sorting Data'!$A$4:$A$51,$A26,'Sorting Data'!$C$4:$C$51,C$25,'Sorting Data'!$D$4:$D$51,1000000)) -> 19612073 | D26: =IF(COUNTIFS('Sorting Data'!$A$4:$A$51,$A26,'Sorting Data'!$C$4:$C$51,D$25,'Sorting Data'!$D$4:$D$51,1000000,'Sorting Data'!$E$4:$E$51,"skipped")>0,"skipped",SUMIFS('Sorting Data'!$F$4:$F$51,'Sorting Data'!$A$4:$A$51,$A26,'Sorting Data'!$C$4:$C$51,D$25,'Sorting Data'!$D$4:$D$51,1000000)) -> 19296305 | E26: =IF(COUNTIFS('Sorting Data'!$A$4:$A$51,$A26,'Sorting Data'!$C$4:$C$51,E$25,'Sorting Data'!$D$4:$D$51,1000000,'Sorting Data'!$E$4:$E$51,"skipped")>0,"skipped",SUMIFS('Sorting Data'!$F$4:$F$51,'Sorting Data'!$A$4:$A$51,$A26,'Sorting Data'!$C$4:$C$51,E$25,'Sorting Data'!$D$4:$D$51,1000000)) -> 21048629
A27: PDQSort | B27: =IF(COUNTIFS('Sorting Data'!$A$4:$A$51,$A27,'Sorting Data'!$C$4:$C$51,B$25,'Sorting Data'!$D$4:$D$51,1000000,'Sorting Data'!$E$4:$E$51,"skipped")>0,"skipped",SUMIFS('Sorting Data'!$F$4:$F$51,'Sorting Data'!$A$4:$A$51,$A27,'Sorting Data'!$C$4:$C$51,B$25,'Sorting Data'!$D$4:$D$51,1000000)) -> 22900121 | C27: =IF(COUNTIFS('Sorting Data'!$A$4:$A$51,$A27,'Sorting Data'!$C$4:$C$51,C$25,'Sorting Data'!$D$4:$D$51,1000000,'Sorting Data'!$E$4:$E$51,"skipped")>0,"skipped",SUMIFS('Sorting Data'!$F$4:$F$51,'Sorting Data'!$A$4:$A$51,$A27,'Sorting Data'!$C$4:$C$51,C$25,'Sorting Data'!$D$4:$D$51,1000000)) -> 16242358 | D27: =IF(COUNTIFS('Sorting Data'!$A$4:$A$51,$A27,'Sorting Data'!$C$4:$C$51,D$25,'Sorting Data'!$D$4:$D$51,1000000,'Sorting Data'!$E$4:$E$51,"skipped")>0,"skipped",SUMIFS('Sorting Data'!$F$4:$F$51,'Sorting Data'!$A$4:$A$51,$A27,'Sorting Data'!$C$4:$C$51,D$25,'Sorting Data'!$D$4:$D$51,1000000)) -> 3500006 | E27: =IF(COUNTIFS('Sorting Data'!$A$4:$A$51,$A27,'Sorting Data'!$C$4:$C$51,E$25,'Sorting Data'!$D$4:$D$51,1000000,'Sorting Data'!$E$4:$E$51,"skipped")>0,"skipped",SUMIFS('Sorting Data'!$F$4:$F$51,'Sorting Data'!$A$4:$A$51,$A27,'Sorting Data'!$C$4:$C$51,E$25,'Sorting Data'!$D$4:$D$51,1000000)) -> 12615859
A28: TwinArray Sort | B28: =IF(COUNTIFS('Sorting Data'!$A$4:$A$51,$A28,'Sorting Data'!$C$4:$C$51,B$25,'Sorting Data'!$D$4:$D$51,1000000,'Sorting Data'!$E$4:$E$51,"skipped")>0,"skipped",SUMIFS('Sorting Data'!$F$4:$F$51,'Sorting Data'!$A$4:$A$51,$A28,'Sorting Data'!$C$4:$C$51,B$25,'Sorting Data'!$D$4:$D$51,1000000)) -> 2000000 | C28: =IF(COUNTIFS('Sorting Data'!$A$4:$A$51,$A28,'Sorting Data'!$C$4:$C$51,C$25,'Sorting Data'!$D$4:$D$51,1000000,'Sorting Data'!$E$4:$E$51,"skipped")>0,"skipped",SUMIFS('Sorting Data'!$F$4:$F$51,'Sorting Data'!$A$4:$A$51,$A28,'Sorting Data'!$C$4:$C$51,C$25,'Sorting Data'!$D$4:$D$51,1000000)) -> 2000000 | D28: =IF(COUNTIFS('Sorting Data'!$A$4:$A$51,$A28,'Sorting Data'!$C$4:$C$51,D$25,'Sorting Data'!$D$4:$D$51,1000000,'Sorting Data'!$E$4:$E$51,"skipped")>0,"skipped",SUMIFS('Sorting Data'!$F$4:$F$51,'Sorting Data'!$A$4:$A$51,$A28,'Sorting Data'!$C$4:$C$51,D$25,'Sorting Data'!$D$4:$D$51,1000000)) -> 2000000 | E28: =IF(COUNTIFS('Sorting Data'!$A$4:$A$51,$A28,'Sorting Data'!$C$4:$C$51,E$25,'Sorting Data'!$D$4:$D$51,1000000,'Sorting Data'!$E$4:$E$51,"skipped")>0,"skipped",SUMIFS('Sorting Data'!$F$4:$F$51,'Sorting Data'!$A$4:$A$51,$A28,'Sorting Data'!$C$4:$C$51,E$25,'Sorting Data'!$D$4:$D$51,1000000)) -> 2000000
A29: Merge sort | B29: =IF(COUNTIFS('Sorting Data'!$A$4:$A$51,$A29,'Sorting Data'!$C$4:$C$51,B$25,'Sorting Data'!$D$4:$D$51,1000000,'Sorting Data'!$E$4:$E$51,"skipped")>0,"skipped",SUMIFS('Sorting Data'!$F$4:$F$51,'Sorting Data'!$A$4:$A$51,$A29,'Sorting Data'!$C$4:$C$51,B$25,'Sorting Data'!$D$4:$D$51,1000000)) -> 18674876 | C29: =IF(COUNTIFS('Sorting Data'!$A$4:$A$51,$A29,'Sorting Data'!$C$4:$C$51,C$25,'Sorting Data'!$D$4:$D$51,1000000,'Sorting Data'!$E$4:$E$51,"skipped")>0,"skipped",SUMIFS('Sorting Data'!$F$4:$F$51,'Sorting Data'!$A$4:$A$51,$A29,'Sorting Data'!$C$4:$C$51,C$25,'Sorting Data'!$D$4:$D$51,1000000)) -> 16437374 | D29: =IF(COUNTIFS('Sorting Data'!$A$4:$A$51,$A29,'Sorting Data'!$C$4:$C$51,D$25,'Sorting Data'!$D$4:$D$51,1000000,'Sorting Data'!$E$4:$E$51,"skipped")>0,"skipped",SUMIFS('Sorting Data'!$F$4:$F$51,'Sorting Data'!$A$4:$A$51,$A29,'Sorting Data'!$C$4:$C$51,D$25,'Sorting Data'!$D$4:$D$51,1000000)) -> 10263816 | E29: =IF(COUNTIFS('Sorting Data'!$A$4:$A$51,$A29,'Sorting Data'!$C$4:$C$51,E$25,'Sorting Data'!$D$4:$D$51,1000000,'Sorting Data'!$E$4:$E$51,"skipped")>0,"skipped",SUMIFS('Sorting Data'!$F$4:$F$51,'Sorting Data'!$A$4:$A$51,$A29,'Sorting Data'!$C$4:$C$51,E$25,'Sorting Data'!$D$4:$D$51,1000000)) -> 18670987
A30: Heap sort | B30: =IF(COUNTIFS('Sorting Data'!$A$4:$A$51,$A30,'Sorting Data'!$C$4:$C$51,B$25,'Sorting Data'!$D$4:$D$51,1000000,'Sorting Data'!$E$4:$E$51,"skipped")>0,"skipped",SUMIFS('Sorting Data'!$F$4:$F$51,'Sorting Data'!$A$4:$A$51,$A30,'Sorting Data'!$C$4:$C$51,B$25,'Sorting Data'!$D$4:$D$51,1000000)) -> 36793933 | C30: =IF(COUNTIFS('Sorting Data'!$A$4:$A$51,$A30,'Sorting Data'!$C$4:$C$51,C$25,'Sorting Data'!$D$4:$D$51,1000000,'Sorting Data'!$E$4:$E$51,"skipped")>0,"skipped",SUMIFS('Sorting Data'!$F$4:$F$51,'Sorting Data'!$A$4:$A$51,$A30,'Sorting Data'!$C$4:$C$51,C$25,'Sorting Data'!$D$4:$D$51,1000000)) -> 37704186 | D30: =IF(COUNTIFS('Sorting Data'!$A$4:$A$51,$A30,'Sorting Data'!$C$4:$C$51,D$25,'Sorting Data'!$D$4:$D$51,1000000,'Sorting Data'!$E$4:$E$51,"skipped")>0,"skipped",SUMIFS('Sorting Data'!$F$4:$F$51,'Sorting Data'!$A$4:$A$51,$A30,'Sorting Data'!$C$4:$C$51,D$25,'Sorting Data'!$D$4:$D$51,1000000)) -> 36002153 | E30: =IF(COUNTIFS('Sorting Data'!$A$4:$A$51,$A30,'Sorting Data'!$C$4:$C$51,E$25,'Sorting Data'!$D$4:$D$51,1000000,'Sorting Data'!$E$4:$E$51,"skipped")>0,"skipped",SUMIFS('Sorting Data'!$F$4:$F$51,'Sorting Data'!$A$4:$A$51,$A30,'Sorting Data'!$C$4:$C$51,E$25,'Sorting Data'!$D$4:$D$51,1000000)) -> 36775940
A31: QuickSort | B31: =IF(COUNTIFS('Sorting Data'!$A$4:$A$51,$A31,'Sorting Data'!$C$4:$C$51,B$25,'Sorting Data'!$D$4:$D$51,1000000,'Sorting Data'!$E$4:$E$51,"skipped")>0,"skipped",SUMIFS('Sorting Data'!$F$4:$F$51,'Sorting Data'!$A$4:$A$51,$A31,'Sorting Data'!$C$4:$C$51,B$25,'Sorting Data'!$D$4:$D$51,1000000)) -> 24880331 | C31: =IF(COUNTIFS('Sorting Data'!$A$4:$A$51,$A31,'Sorting Data'!$C$4:$C$51,C$25,'Sorting Data'!$D$4:$D$51,1000000,'Sorting Data'!$E$4:$E$51,"skipped")>0,"skipped",SUMIFS('Sorting Data'!$F$4:$F$51,'Sorting Data'!$A$4:$A$51,$A31,'Sorting Data'!$C$4:$C$51,C$25,'Sorting Data'!$D$4:$D$51,1000000)) -> 25593387 | D31: =IF(COUNTIFS('Sorting Data'!$A$4:$A$51,$A31,'Sorting Data'!$C$4:$C$51,D$25,'Sorting Data'!$D$4:$D$51,1000000,'Sorting Data'!$E$4:$E$51,"skipped")>0,"skipped",SUMIFS('Sorting Data'!$F$4:$F$51,'Sorting Data'!$A$4:$A$51,$A31,'Sorting Data'!$C$4:$C$51,D$25,'Sorting Data'!$D$4:$D$51,1000000)) -> 18582482 | E31: =IF(COUNTIFS('Sorting Data'!$A$4:$A$51,$A31,'Sorting Data'!$C$4:$C$51,E$25,'Sorting Data'!$D$4:$D$51,1000000,'Sorting Data'!$E$4:$E$51,"skipped")>0,"skipped",SUMIFS('Sorting Data'!$F$4:$F$51,'Sorting Data'!$A$4:$A$51,$A31,'Sorting Data'!$C$4:$C$51,E$25,'Sorting Data'!$D$4:$D$51,1000000)) -> 512870978
A33: Comparisons, n = 100,000,000
A35: Algorithm | B35: Random | C35: Nearly sorted | D35: Reverse sorted | E35: Duplicates
A36: AlphaDev sort | B36: =IF(COUNTIFS('Sorting Data'!$A$4:$A$51,$A36,'Sorting Data'!$C$4:$C$51,B$35,'Sorting Data'!$D$4:$D$51,100000000,'Sorting Data'!$E$4:$E$51,"skipped")>0,"skipped",SUMIFS('Sorting Data'!$F$4:$F$51,'Sorting Data'!$A$4:$A$51,$A36,'Sorting Data'!$C$4:$C$51,B$35,'Sorting Data'!$D$4:$D$51,100000000)) -> 2968822575 | C36: =IF(COUNTIFS('Sorting Data'!$A$4:$A$51,$A36,'Sorting Data'!$C$4:$C$51,C$35,'Sorting Data'!$D$4:$D$51,100000000,'Sorting Data'!$E$4:$E$51,"skipped")>0,"skipped",SUMIFS('Sorting Data'!$F$4:$F$51,'Sorting Data'!$A$4:$A$51,$A36,'Sorting Data'!$C$4:$C$51,C$35,'Sorting Data'!$D$4:$D$51,100000000)) -> 2641001849 | D36: =IF(COUNTIFS('Sorting Data'!$A$4:$A$51,$A36,'Sorting Data'!$C$4:$C$51,D$35,'Sorting Data'!$D$4:$D$51,100000000,'Sorting Data'!$E$4:$E$51,"skipped")>0,"skipped",SUMIFS('Sorting Data'!$F$4:$F$51,'Sorting Data'!$A$4:$A$51,$A36,'Sorting Data'!$C$4:$C$51,D$35,'Sorting Data'!$D$4:$D$51,100000000)) -> 2604863029 | E36: =IF(COUNTIFS('Sorting Data'!$A$4:$A$51,$A36,'Sorting Data'!$C$4:$C$51,E$35,'Sorting Data'!$D$4:$D$51,100000000,'Sorting Data'!$E$4:$E$51,"skipped")>0,"skipped",SUMIFS('Sorting Data'!$F$4:$F$51,'Sorting Data'!$A$4:$A$51,$A36,'Sorting Data'!$C$4:$C$51,E$35,'Sorting Data'!$D$4:$D$51,100000000)) -> 2721581709
A37: PDQSort | B37: =IF(COUNTIFS('Sorting Data'!$A$4:$A$51,$A37,'Sorting Data'!$C$4:$C$51,B$35,'Sorting Data'!$D$4:$D$51,100000000,'Sorting Data'!$E$4:$E$51,"skipped")>0,"skipped",SUMIFS('Sorting Data'!$F$4:$F$51,'Sorting Data'!$A$4:$A$51,$A37,'Sorting Data'!$C$4:$C$51,B$35,'Sorting Data'!$D$4:$D$51,100000000)) -> 3104604878 | C37: =IF(COUNTIFS('Sorting Data'!$A$4:$A$51,$A37,'Sorting Data'!$C$4:$C$51,C$35,'Sorting Data'!$D$4:$D$51,100000000,'Sorting Data'!$E$4:$E$51,"skipped")>0,"skipped",SUMIFS('Sorting Data'!$F$4:$F$51,'Sorting Data'!$A$4:$A$51,$A37,'Sorting Data'!$C$4:$C$51,C$35,'Sorting Data'!$D$4:$D$51,100000000)) -> 2311483634 | D37: =IF(COUNTIFS('Sorting Data'!$A$4:$A$51,$A37,'Sorting Data'!$C$4:$C$51,D$35,'Sorting Data'!$D$4:$D$51,100000000,'Sorting Data'!$E$4:$E$51,"skipped")>0,"skipped",SUMIFS('Sorting Data'!$F$4:$F$51,'Sorting Data'!$A$4:$A$51,$A37,'Sorting Data'!$C$4:$C$51,D$35,'Sorting Data'!$D$4:$D$51,100000000)) -> 300000001 | E37: =IF(COUNTIFS('Sorting Data'!$A$4:$A$51,$A37,'Sorting Data'!$C$4:$C$51,E$35,'Sorting Data'!$D$4:$D$51,100000000,'Sorting Data'!$E$4:$E$51,"skipped")>0,"skipped",SUMIFS('Sorting Data'!$F$4:$F$51,'Sorting Data'!$A$4:$A$51,$A37,'Sorting Data'!$C$4:$C$51,E$35,'Sorting Data'!$D$4:$D$51,100000000)) -> 1239307200
A38: TwinArray Sort | B38: =IF(COUNTIFS('Sorting Data'!$A$4:$A$51,$A38,'Sorting Data'!$C$4:$C$51,B$35,'Sorting Data'!$D$4:$D$51,100000000,'Sorting Data'!$E$4:$E$51,"skipped")>0,"skipped",SUMIFS('Sorting Data'!$F$4:$F$51,'Sorting Data'!$A$4:$A$51,$A38,'Sorting Data'!$C$4:$C$51,B$35,'Sorting Data'!$D$4:$D$51,100000000)) -> 200000000 | C38: =IF(COUNTIFS('Sorting Data'!$A$4:$A$51,$A38,'Sorting Data'!$C$4:$C$51,C$35,'Sorting Data'!$D$4:$D$51,100000000,'Sorting Data'!$E$4:$E$51,"skipped")>0,"skipped",SUMIFS('Sorting Data'!$F$4:$F$51,'Sorting Data'!$A$4:$A$51,$A38,'Sorting Data'!$C$4:$C$51,C$35,'Sorting Data'!$D$4:$D$51,100000000)) -> 200000000 | D38: =IF(COUNTIFS('Sorting Data'!$A$4:$A$51,$A38,'Sorting Data'!$C$4:$C$51,D$35,'Sorting Data'!$D$4:$D$51,100000000,'Sorting Data'!$E$4:$E$51,"skipped")>0,"skipped",SUMIFS('Sorting Data'!$F$4:$F$51,'Sorting Data'!$A$4:$A$51,$A38,'Sorting Data'!$C$4:$C$51,D$35,'Sorting Data'!$D$4:$D$51,100000000)) -> 200000000 | E38: =IF(COUNTIFS('Sorting Data'!$A$4:$A$51,$A38,'Sorting Data'!$C$4:$C$51,E$35,'Sorting Data'!$D$4:$D$51,100000000,'Sorting Data'!$E$4:$E$51,"skipped")>0,"skipped",SUMIFS('Sorting Data'!$F$4:$F$51,'Sorting Data'!$A$4:$A$51,$A38,'Sorting Data'!$C$4:$C$51,E$35,'Sorting Data'!$D$4:$D$51,100000000)) -> 200000000
A39: Merge sort | B39: =IF(COUNTIFS('Sorting Data'!$A$4:$A$51,$A39,'Sorting Data'!$C$4:$C$51,B$35,'Sorting Data'!$D$4:$D$51,100000000,'Sorting Data'!$E$4:$E$51,"skipped")>0,"skipped",SUMIFS('Sorting Data'!$F$4:$F$51,'Sorting Data'!$A$4:$A$51,$A39,'Sorting Data'!$C$4:$C$51,B$35,'Sorting Data'!$D$4:$D$51,100000000)) -> 2532923647 | C39: =IF(COUNTIFS('Sorting Data'!$A$4:$A$51,$A39,'Sorting Data'!$C$4:$C$51,C$35,'Sorting Data'!$D$4:$D$51,100000000,'Sorting Data'!$E$4:$E$51,"skipped")>0,"skipped",SUMIFS('Sorting Data'!$F$4:$F$51,'Sorting Data'!$A$4:$A$51,$A39,'Sorting Data'!$C$4:$C$51,C$35,'Sorting Data'!$D$4:$D$51,100000000)) -> 2303890896 | D39: =IF(COUNTIFS('Sorting Data'!$A$4:$A$51,$A39,'Sorting Data'!$C$4:$C$51,D$35,'Sorting Data'!$D$4:$D$51,100000000,'Sorting Data'!$E$4:$E$51,"skipped")>0,"skipped",SUMIFS('Sorting Data'!$F$4:$F$51,'Sorting Data'!$A$4:$A$51,$A39,'Sorting Data'!$C$4:$C$51,D$35,'Sorting Data'!$D$4:$D$51,100000000)) -> 1364054534 | E39: =IF(COUNTIFS('Sorting Data'!$A$4:$A$51,$A39,'Sorting Data'!$C$4:$C$51,E$35,'Sorting Data'!$D$4:$D$51,100000000,'Sorting Data'!$E$4:$E$51,"skipped")>0,"skipped",SUMIFS('Sorting Data'!$F$4:$F$51,'Sorting Data'!$A$4:$A$51,$A39,'Sorting Data'!$C$4:$C$51,E$35,'Sorting Data'!$D$4:$D$51,100000000)) -> 2532187444
A40: Heap sort | B40: =IF(COUNTIFS('Sorting Data'!$A$4:$A$51,$A40,'Sorting Data'!$C$4:$C$51,B$35,'Sorting Data'!$D$4:$D$51,100000000,'Sorting Data'!$E$4:$E$51,"skipped")>0,"skipped",SUMIFS('Sorting Data'!$F$4:$F$51,'Sorting Data'!$A$4:$A$51,$A40,'Sorting Data'!$C$4:$C$51,B$35,'Sorting Data'!$D$4:$D$51,100000000)) -> 5012885387 | C40: =IF(COUNTIFS('Sorting Data'!$A$4:$A$51,$A40,'Sorting Data'!$C$4:$C$51,C$35,'Sorting Data'!$D$4:$D$51,100000000,'Sorting Data'!$E$4:$E$51,"skipped")>0,"skipped",SUMIFS('Sorting Data'!$F$4:$F$51,'Sorting Data'!$A$4:$A$51,$A40,'Sorting Data'!$C$4:$C$51,C$35,'Sorting Data'!$D$4:$D$51,100000000)) -> 5115790973 | D40: =IF(COUNTIFS('Sorting Data'!$A$4:$A$51,$A40,'Sorting Data'!$C$4:$C$51,D$35,'Sorting Data'!$D$4:$D$51,100000000,'Sorting Data'!$E$4:$E$51,"skipped")>0,"skipped",SUMIFS('Sorting Data'!$F$4:$F$51,'Sorting Data'!$A$4:$A$51,$A40,'Sorting Data'!$C$4:$C$51,D$35,'Sorting Data'!$D$4:$D$51,100000000)) -> 4924225375 | E40: =IF(COUNTIFS('Sorting Data'!$A$4:$A$51,$A40,'Sorting Data'!$C$4:$C$51,E$35,'Sorting Data'!$D$4:$D$51,100000000,'Sorting Data'!$E$4:$E$51,"skipped")>0,"skipped",SUMIFS('Sorting Data'!$F$4:$F$51,'Sorting Data'!$A$4:$A$51,$A40,'Sorting Data'!$C$4:$C$51,E$35,'Sorting Data'!$D$4:$D$51,100000000)) -> 5009558141
A41: QuickSort | B41: =IF(COUNTIFS('Sorting Data'!$A$4:$A$51,$A41,'Sorting Data'!$C$4:$C$51,B$35,'Sorting Data'!$D$4:$D$51,100000000,'Sorting Data'!$E$4:$E$51,"skipped")>0,"skipped",SUMIFS('Sorting Data'!$F$4:$F$51,'Sorting Data'!$A$4:$A$51,$A41,'Sorting Data'!$C$4:$C$51,B$35,'Sorting Data'!$D$4:$D$51,100000000)) -> 3389431225 | C41: =IF(COUNTIFS('Sorting Data'!$A$4:$A$51,$A41,'Sorting Data'!$C$4:$C$51,C$35,'Sorting Data'!$D$4:$D$51,100000000,'Sorting Data'!$E$4:$E$51,"skipped")>0,"skipped",SUMIFS('Sorting Data'!$F$4:$F$51,'Sorting Data'!$A$4:$A$51,$A41,'Sorting Data'!$C$4:$C$51,C$35,'Sorting Data'!$D$4:$D$51,100000000)) -> 4145189294 | D41: =IF(COUNTIFS('Sorting Data'!$A$4:$A$51,$A41,'Sorting Data'!$C$4:$C$51,D$35,'Sorting Data'!$D$4:$D$51,100000000,'Sorting Data'!$E$4:$E$51,"skipped")>0,"skipped",SUMIFS('Sorting Data'!$F$4:$F$51,'Sorting Data'!$A$4:$A$51,$A41,'Sorting Data'!$C$4:$C$51,D$35,'Sorting Data'!$D$4:$D$51,100000000)) -> 2522736699 | E41: =IF(COUNTIFS('Sorting Data'!$A$4:$A$51,$A41,'Sorting Data'!$C$4:$C$51,E$35,'Sorting Data'!$D$4:$D$51,100000000,'Sorting Data'!$E$4:$E$51,"skipped")>0,"skipped",SUMIFS('Sorting Data'!$F$4:$F$51,'Sorting Data'!$A$4:$A$51,$A41,'Sorting Data'!$C$4:$C$51,E$35,'Sorting Data'!$D$4:$D$51,100000000)) -> skipped
A43: Growth when n goes from 1M to 100M (time at 100M / time at 1M). Theory: n log n = x133, O(n + k) = x100
A45: Algorithm | B45: Random | C45: Nearly sorted | D45: Reverse sorted | E45: Duplicates
A46: AlphaDev sort | B46: =IF(ISNUMBER(B16),B16/B6,"skipped") -> 133.25913 | C46: =IF(ISNUMBER(C16),C16/C6,"skipped") -> 117.13529 | D46: =IF(ISNUMBER(D16),D16/D6,"skipped") -> 117.83484 | E46: =IF(ISNUMBER(E16),E16/E6,"skipped") -> 105.59584
A47: PDQSort | B47: =IF(ISNUMBER(B17),B17/B7,"skipped") -> 140.84193 | C47: =IF(ISNUMBER(C17),C17/C7,"skipped") -> 135.25596 | D47: =IF(ISNUMBER(D17),D17/D7,"skipped") -> 89.815166 | E47: =IF(ISNUMBER(E17),E17/E7,"skipped") -> 99.774563
A48: TwinArray Sort | B48: =IF(ISNUMBER(B18),B18/B8,"skipped") -> 248.22154 | C48: =IF(ISNUMBER(C18),C18/C8,"skipped") -> 105.84562 | D48: =IF(ISNUMBER(D18),D18/D8,"skipped") -> 90.151269 | E48: =IF(ISNUMBER(E18),E18/E8,"skipped") -> 65.352941
A49: Merge sort | B49: =IF(ISNUMBER(B19),B19/B9,"skipped") -> 131.375 | C49: =IF(ISNUMBER(C19),C19/C9,"skipped") -> 130.23234 | D49: =IF(ISNUMBER(D19),D19/D9,"skipped") -> 122.91557 | E49: =IF(ISNUMBER(E19),E19/E9,"skipped") -> 108.65984
A50: Heap sort | B50: =IF(ISNUMBER(B20),B20/B10,"skipped") -> 243.39168 | C50: =IF(ISNUMBER(C20),C20/C10,"skipped") -> 114.73156 | D50: =IF(ISNUMBER(D20),D20/D10,"skipped") -> 118.11186 | E50: =IF(ISNUMBER(E20),E20/E10,"skipped") -> 181.48075
...

Sheet Time vs Size
A1: Time vs dataset size, random data (formulas)
A3: Algorithm | B3: 1,000,000 | C3: 100,000,000
A4: AlphaDev sort | B4: ='Sorting Summary'!B6 -> 73.94 | C4: ='Sorting Summary'!B16 -> 9853.18
A5: PDQSort | B5: ='Sorting Summary'!B7 -> 72.12 | C5: ='Sorting Summary'!B17 -> 10157.52
A6: TwinArray Sort | B6: ='Sorting Summary'!B8 -> 16.34 | C6: ='Sorting Summary'!B18 -> 4055.94
A7: Merge sort | B7: ='Sorting Summary'!B9 -> 96.32 | C7: ='Sorting Summary'!B19 -> 12654.04
A8: Heap sort | B8: ='Sorting Summary'!B10 -> 118.77 | C8: ='Sorting Summary'!B20 -> 28907.63
A9: QuickSort | B9: ='Sorting Summary'!B11 -> 66.72 | C9: ='Sorting Summary'!B21 -> 8698.53
A11: Y axis is logarithmic so 1M and 100M fit on one chart.

Sheet Search
A1: Search results: 1000 random queries on the sorted random data
A3: Algorithm | B3: n | C3: Avg time (ns) | D3: Worst time (ns) | E3: Avg comparisons | F3: Worst comparisons | G3: Extra memory (MB) | H3: Found
A4: Binary search | B4: 1000000 | C4: 19 | D4: 23 | E4: 37.4 | F4: 40 | G4: 0 | H4: 646
A5: Exponential search | B5: 1000000 | C5: 29.2 | D5: 35 | E5: 53.8 | F5: 59 | G5: 0 | H5: 646
A6: M-way tree (M=10) | B6: 1000000 | C6: 29.2 | D6: 42 | E6: 36.8 | F6: 60 | G6: 0.99 | H6: 646
A7: Binary search | B7: 100000000 | C7: 29.3 | D7: 35 | E7: 50.8 | F7: 54 | G7: 0 | H7: 638
A8: Exponential search | B8: 100000000 | C8: 49.1 | D8: 74 | E8: 73.4 | F8: 78 | G8: 0 | H8: 638
A9: M-way tree (M=10) | B9: 100000000 | C9: 38.2 | D9: 59 | E9: 47.8 | F9: 75 | G9: 98.9 | H9: 638
A11: M-way tree build: 12,351 nodes in 1.39 ms (1M); 1,234,575 nodes in 152.91 ms (100M). Build is done once and not included in search times.
A13: Algorithm | B13: Avg ns, 1M | C13: Avg ns, 100M | D13: Time growth | E13: Avg cmp, 1M | F13: Avg cmp, 100M | G13: Extra cmp
A14: =A4 -> Binary search | B14: =C4 -> 19 | C14: =C7 -> 29.3 | D14: =C14/B14 -> 1.5421053 | E14: =E4 -> 37.4 | F14: =E7 -> 50.8 | G14: =F14-E14 -> 13.4
A15: =A5 -> Exponential search | B15: =C5 -> 29.2 | C15: =C8 -> 49.1 | D15: =C15/B15 -> 1.6815068 | E15: =E5 -> 53.8 | F15: =E8 -> 73.4 | G15: =F15-E15 -> 19.6
A16: =A6 -> M-way tree (M=10) | B16: =C6 -> 29.2 | C16: =C9 -> 38.2 | D16: =C16/B16 -> 1.3082192 | E16: =E6 -> 36.8 | F16: =E9 -> 47.8 | G16: =F16-E16 -> 11
A17: Data grew x100; log2(n) grew by only | D17: =LOG(100000000,2)-LOG(1000000,2) -> 6.6438562

Sheet OpenMP
A1: Bonus: parallel merge sort with OpenMP, random data (median of 3 runs)
A3: Threads | B3: Time 1M (ms) | C3: Time 100M (ms) | D3: Speedup 1M | E3: Speedup 100M | F3: Ideal speedup | G3: Efficiency 100M
A4: 1 | B4: 94.01 | C4: 12477.39 | D4: =$B$4/B4 -> 1 | E4: =$C$4/C4 -> 1 | F4: =A4 -> 1 | G4: =E4/A4 -> 1
A5: 2 | B5: 50.01 | C5: 6482.86 | D5: =$B$4/B5 -> 1.879824 | E5: =$C$4/C5 -> 1.9246737 | F5: =A5 -> 2 | G5: =E5/A5 -> 0.96233684
A6: 4 | B6: 38.84 | C6: 4519.18 | D6: =$B$4/B6 -> 2.4204428 | E6: =$C$4/C6 -> 2.7609854 | F6: =A6 -> 4 | G6: =E6/A6 -> 0.69024635
A7: 8 | B7: 25.94 | C7: 3023.86 | D7: =$B$4/B7 -> 3.6241326 | E7: =$C$4/C7 -> 4.1263121 | F7: =A7 -> 8 | G7: =E7/A7 -> 0.51578901
A8: 16 | B8: 22.71 | C8: 2296.24 | D8: =$B$4/B8 -> 4.1395861 | E8: =$C$4/C8 -> 5.4338353 | F8: =A8 -> 16 | G8: =E8/A8 -> 0.33961471
A9: 20 | B9: 22.16 | C9: 2140.63 | D9: =$B$4/B9 -> 4.2423285 | E9: =$C$4/C9 -> 5.8288401 | F9: =A9 -> 20 | G9: =E9/A9 -> 0.29144201
A11: Amdahl's law: serial fraction f from the 20-thread speedup S, using 1/S = f + (1-f)/p
A12: f (100M) | B12: =(1/E9-1/A9)/(1-1/A9) -> 0.12795865
A13: Max speedup with infinite threads = 1/f | B13: =1/B12 -> 7.8150245
A15: i7-12800H: 6 performance cores (12 threads with hyper-threading) + 8 efficiency cores = 20 threads, so gains flatten after about 8 threads.
